Workbook
Name ProjectType: [1]Sheet1!$A$1:$A$2
Name ProjectType: 'Feeder Tables'!$A$1:$A$2

Sheet AMI & Rent
A1: Inclusionary and 421-a AMIs and Utility Allowances
A3: 2024 Area Median Income
A5: 155300 | B5: for a family of four
A6: 2752 | B6: 2 BR 100% FMR (2024)
A7: 0.3 | B7: Rent Burden
A9: Step 1: Select all applicable tenant-paid utility allowances from the table below. Note: these allowances are for 421-a and Inclusionary Programs only.
A10: Projects also going through HPD loan programs must defer to allowances and rules provided by HPD loan programs.
B12: 2024 Utility Allowances for 421-a and Inclusionary Programs Only
B14: Apartment Electricity only | C14: Cooking | E14: Heat | J14: Hot Water | N14: Project Total
C15: Electric Stove | D15: Gas Stove | E15: Electric Heat - Cold Climate Air Source Heat Pump (ccASHP)1 | F15: Electric Heat - Other2 | G15: Gas Heat | H15: Oil Heat | J15: Electric Hot Water - Heat Pump | K15: Electric Hot Water - Other | L15: Gas Hot Water | M15: Oil Hot Water
A16: Select -->> | B16: Tenant Pays | C16: Tenant Pays | D16: N/A or owner pays | E16: N/A or owner pays | F16: N/A or owner pays | G16: N/A or owner pays | H16: N/A - owner pays | J16: N/A or owner pays | K16: N/A or owner pays | L16: N/A or owner pays | M16: N/A or owner pays
A17: studio | B17: =IF($B$16="Tenant Pays", 74, 0) -> 74 | C17: =IF($C$16="Tenant Pays", 11, 0) -> 11 | D17: =IF($D$16="Tenant Pays", 25, 0) -> 0 | E17: =IF($E$16="Tenant Pays", 24,0) -> 0 | F17: =IF($F$16="Tenant Pays", 42, 0) -> 0 | G17: =IF($G$16="Tenant Pays", 65,0) -> 0 | H17: =IF($H$16="Tenant Pays", 116,0) -> 0 | J17: =IF($J$16="Tenant Pays", 16,0) -> 0 | K17: =IF($K$16="Tenant Pays", 38,0) -> 0 | L17: =IF($L$16="Tenant Pays", 20,0) -> 0 | M17: =IF($M$16="Tenant Pays", 35, 0) -> 0 | N17: =SUM(B17:M17) -> 85
A18: 1 BR | B18: =IF($B$16="Tenant Pays", 84, 0) -> 84 | C18: =IF($C$16="Tenant Pays", 13, 0) -> 13 | D18: =IF($D$16="Tenant Pays", 28, 0) -> 0 | E18: =IF($E$16="Tenant Pays", 28,0) -> 0 | F18: =IF($F$16="Tenant Pays", 49, 0) -> 0 | G18: =IF($G$16="Tenant Pays", 77,0) -> 0 | H18: =IF($H$16="Tenant Pays", 137,0) -> 0 | J18: =IF($J$16="Tenant Pays", 27,0) -> 0 | K18: =IF($K$16="Tenant Pays", 66,0) -> 0 | L18: =IF($L$16="Tenant Pays", 23,0) -> 0 | M18: =IF($M$16="Tenant Pays", 41, 0) -> 0 | N18: =SUM(B18:M18) -> 97
A19: 2 BR | B19: =IF($B$16="Tenant Pays", 109, 0) -> 109 | C19: =IF($C$16="Tenant Pays", 19, 0) -> 19 | D19: =IF($D$16="Tenant Pays", 33, 0) -> 0 | E19: =IF($E$16="Tenant Pays", 39,0) -> 0 | F19: =IF($F$16="Tenant Pays", 68, 0) -> 0 | G19: =IF($G$16="Tenant Pays", 89,0) -> 0 | H19: =IF($H$16="Tenant Pays", 156,0) -> 0 | J19: =IF($J$16="Tenant Pays", 55,0) -> 0 | K19: =IF($K$16="Tenant Pays", 132,0) -> 0 | L19: =IF($L$16="Tenant Pays", 34,0) -> 0 | M19: =IF($M$16="Tenant Pays", 60, 0) -> 0 | N19: =SUM(B19:M19) -> 128
A20: 3 BR | B20: =IF($B$16="Tenant Pays", 134, 0) -> 134 | C20: =IF($C$16="Tenant Pays", 25, 0) -> 25 | D20: =IF($D$16="Tenant Pays", 37, 0) -> 0 | E20: =IF($E$16="Tenant Pays", 50,0) -> 0 | F20: =IF($F$16="Tenant Pays", 87, 0) -> 0 | G20: =IF($G$16="Tenant Pays", 98,0) -> 0 | H20: =IF($H$16="Tenant Pays", 175,0) -> 0 | J20: =IF($J$16="Tenant Pays", 81,0) -> 0 | K20: =IF($K$16="Tenant Pays", 198,0) -> 0 | L20: =IF($L$16="Tenant Pays", 44,0) -> 0 | M20: =IF($M$16="Tenant Pays", 78, 0) -> 0 | N20: =SUM(B20:M20) -> 159
A21: 4 BR | B21: =IF($B$16="Tenant Pays", 160, 0) -> 160 | C21: =IF($C$16="Tenant Pays", 31, 0) -> 31 | D21: =IF($D$16="Tenant Pays", 42, 0) -> 0 | E21: =IF($E$16="Tenant Pays", 59,0) -> 0 | F21: =IF($F$16="Tenant Pays", 103, 0) -> 0 | G21: =IF($G$16="Tenant Pays", 109,0) -> 0 | H21: =IF($H$16="Tenant Pays", 195,0) -> 0 | J21: =IF($J$16="Tenant Pays", 95,0) -> 0 | K21: =IF($K$16="Tenant Pays", 232,0) -> 0 | L21: =IF($L$16="Tenant Pays", 54,0) -> 0 | M21: =IF($M$16="Tenant Pays", 97, 0) -> 0 | N21: =SUM(B21:M21) -> 191
A22: 5 BR | B22: =IF($B$16="Tenant Pays", 186, 0) -> 186 | C22: =IF($C$16="Tenant Pays", 37, 0) -> 37 | D22: =IF($D$16="Tenant Pays", 46, 0) -> 0 | E22: =IF($E$16="Tenant Pays", 68,0) -> 0 | F22: =IF($F$16="Tenant Pays", 119, 0) -> 0 | G22: =IF($G$16="Tenant Pays", 120,0) -> 0 | H22: =IF($H$16="Tenant Pays", 214,0) -> 0 | J22: =IF($J$16="Tenant Pays", 108,0) -> 0 | K22: =IF($K$16="Tenant Pays", 266,0) -> 0 | L22: =IF($L$16="Tenant Pays", 65,0) -> 0 | M22: =IF($M$16="Tenant Pays", 115, 0) -> 0 | N22: =SUM(B22:M22) -> 223
A24: As of: | B24: 45292
B26: Footnotes
B27: (1) Product must be listed on the NEEP Cold Climate Air Source Heat Pump (ccASHP) Product List: https://ashp.neep.org/#!/
B28: (2) Other: e.g. Electric Resistance Heating, Electric PTACs, Electric Furnace
A30: Step 2: The total applicable tenant-paid utility allowances for the project are removed from the Underwritten Rents published below.
C32: 0.3 | D32: of AMI | E32: =AMI_Table!$E$13*'AMI & Rent'!$C32 -> 46590 | F32: for a family of four
L33: Income
G34: Gross Rent (No utilities removed) | H34: Underwritten Rent (Utilities Removed) | J34: HH Size | K34: HH Factor | L34: Limit
F35: Income | J35: =J36-1 -> 1 | K35: 0.7 | L35: =AMI_Table!$B$13*'AMI & Rent'!$C32 -> 32610
D36: HH size | E36: HH factor | F36: Limit | J36: =J37-1 -> 2 | K36: =K35+0.1 -> 0.8 | L36: =AMI_Table!$C$13*'AMI & Rent'!$C32 -> 37290
C37: studio | D37: 1 | E37: 0.7 | F37: =AMI_Table!$B$13*'AMI & Rent'!$C32 -> 32610 | G37: =ROUNDDOWN(F37*$A$7/12,0) -> 815 | H37: =G37-N17 -> 730 | J37: =J38-1 -> 3 | K37: =K36+0.1 -> 0.9 | L37: =AMI_Table!$D$13*'AMI & Rent'!$C32 -> 41940
C38: 1 BR | D38: 1.5 | E38: 0.75 | F38: =AVERAGE(L35:L36) -> 34950 | G38: =ROUNDDOWN(F38*$A$7/12,0) -> 873 | H38: =G38-N18 -> 776 | J38: =J39-1 -> 4 | K38: =K37+0.1 -> 1 | L38: =AMI_Table!$E$13*'AMI & Rent'!$C32 -> 46590
C39: 2 BR | D39: 3 | E39: 0.9 | F39: =L37 -> 41940 | G39: =ROUNDDOWN(F39*$A$7/12,0) -> 1048 | H39: =G39-N19 -> 920 | J39: =J40-1 -> 5 | K39: =K38+0.08 -> 1.08 | L39: =AMI_Table!$F$13*'AMI & Rent'!$C32 -> 50310
C40: 3 BR | D40: 4.5 | E40: 1.04 | F40: =AVERAGE(L38:L39) -> 48450 | G40: =ROUNDDOWN(F40*$A$7/12,0) -> 1211 | H40: =G40-N20 -> 1052 | J40: =J41-1 -> 6 | K40: =K39+0.08 -> 1.16 | L40: =AMI_Table!$G$13*'AMI & Rent'!$C32 -> 54030
C41: 4 BR | D41: 6 | E41: 1.16 | F41: =L40 -> 54030 | G41: =ROUNDDOWN(F41*$A$7/12,0) -> 1350 | H41: =G41-N21 -> 1159 | J41: =J42-1 -> 7 | K41: =K40+0.08 -> 1.24 | L41: =AMI_Table!$H$13*'AMI & Rent'!$C32 -> 57780
C42: 5 BR | D42: 7.5 | E42: =1.28 -> 1.28 | F42: =AVERAGE(L41:L42) -> 59640 | G42: =ROUNDDOWN(F42*$A$7/12,0) -> 1491 | H42: =G42-N22 -> 1268 | J42: 8 | K42: =K41+0.08 -> 1.32 | L42: =AMI_Table!$I$13*'AMI & Rent'!$C32 -> 61500
C45: 0.4 | D45: of AMI | E45: =AMI_Table!$E$13*'AMI & Rent'!$C45 -> 62120 | F45: for a family of four
L46: Income
G47: Gross Rent (No utilities removed) | H47: Underwritten Rent (Utilities Removed) | J47: HH Size | K47: HH Factor | L47: Limit
F48: Income | J48: =J49-1 -> 1 | K48: 0.7 | L48: =AMI_Table!$B$13*'AMI & Rent'!$C45 -> 43480
D49: HH size | E49: HH factor | F49: Limit | J49: =J50-1 -> 2 | K49: =K48+0.1 -> 0.8 | L49: =AMI_Table!$C$13*'AMI & Rent'!$C45 -> 49720
C50: studio | D50: 1 | E50: 0.7 | F50: =AMI_Table!$B$13*'AMI & Rent'!$C45 -> 43480 | G50: =ROUNDDOWN(F50*$A$7/12,0) -> 1087 | H50: =G50-N17 -> 1002 | J50: =J51-1 -> 3 | K50: =K49+0.1 -> 0.9 | L50: =AMI_Table!$D$13*'AMI & Rent'!$C45 -> 55920
C51: 1 BR | D51: 1.5 | E51: 0.75 | F51: =AVERAGE(L48:L49) -> 46600 | G51: =ROUNDDOWN(F51*$A$7/12,0) -> 1165 | H51: =G51-N18 -> 1068 | J51: =J52-1 -> 4 | K51: =K50+0.1 -> 1 | L51: =AMI_Table!$E$13*'AMI & Rent'!$C45 -> 62120
...

Sheet AMI_Table
A1: ='[1]AMI & Rent'!A1 -> 2024 Area Median Income
B2: =VLOOKUP(B3,'[1]AMI & Rent'!$K$32:$L$39,2,FALSE) -> 0.7 | C2: =VLOOKUP(C3,'[1]AMI & Rent'!$K$32:$L$39,2,FALSE) -> 0.8 | D2: =VLOOKUP(D3,'[1]AMI & Rent'!$K$32:$L$39,2,FALSE) -> 0.9 | E2: =VLOOKUP(E3,'[1]AMI & Rent'!$K$32:$L$39,2,FALSE) -> 1 | F2: =VLOOKUP(F3,'[1]AMI & Rent'!$K$32:$L$39,2,FALSE) -> 1.08 | G2: =VLOOKUP(G3,'[1]AMI & Rent'!$K$32:$L$39,2,FALSE) -> 1.16 | H2: =VLOOKUP(H3,'[1]AMI & Rent'!$K$32:$L$39,2,FALSE) -> 1.24 | I2: =VLOOKUP(I3,'[1]AMI & Rent'!$K$32:$L$39,2,FALSE) -> 1.32
B3: 1 | C3: =B3+1 -> 2 | D3: =C3+1 -> 3 | E3: =D3+1 -> 4 | F3: =E3+1 -> 5 | G3: =F3+1 -> 6 | H3: =G3+1 -> 7 | I3: =H3+1 -> 8
A4: 0.1 | B4: =B8*0.2 -> 10870 | C4: =C8*0.2 -> 12430 | D4: =D8*0.2 -> 13980 | E4: =E8*0.2 -> 15530 | F4: =F8*0.2 -> 16770 | G4: =G8*0.2 -> 18010 | H4: =H8*0.2 -> 19260 | I4: =I8*0.2 -> 20500
A5: =+A4+10% -> 0.2 | B5: =B8*0.4 -> 21740 | C5: =C8*0.4 -> 24860 | D5: =D8*0.4 -> 27960 | E5: =E8*0.4 -> 31060 | F5: =F8*0.4 -> 33540 | G5: =G8*0.4 -> 36020 | H5: =H8*0.4 -> 38520 | I5: =I8*0.4 -> 41000
A6: =+A5+10% -> 0.3 | B6: =B8*0.6 -> 32610 | C6: =C8*0.6 -> 37290 | D6: =D8*0.6 -> 41940 | E6: =E8*0.6 -> 46590 | F6: =F8*0.6 -> 50310 | G6: =G8*0.6 -> 54030 | H6: =H8*0.6 -> 57780 | I6: =I8*0.6 -> 61500
A7: =+A6+10% -> 0.4 | B7: =B8*0.8 -> 43480 | C7: =C8*0.8 -> 49720 | D7: =D8*0.8 -> 55920 | E7: =E8*0.8 -> 62120 | F7: =F8*0.8 -> 67080 | G7: =G8*0.8 -> 72040 | H7: =H8*0.8 -> 77040 | I7: =I8*0.8 -> 82000
A8: =+A7+10% -> 0.5 | B8: 54350 | C8: 62150 | D8: 69900 | E8: 77650 | F8: 83850 | G8: 90050 | H8: 96300 | I8: 102500 | J8: The 50% values are hard coded to resolve the minor disagreement between HDC's formulas and the 2024 HUD standards. These disagreements have arisen due to a change in HUD's income limit formula.
A9: =+A8+10% -> 0.6 | B9: =B8*1.2 -> 65220 | C9: =C8*1.2 -> 74580 | D9: =D8*1.2 -> 83880 | E9: =E8*1.2 -> 93180 | F9: =F8*1.2 -> 100620 | G9: =G8*1.2 -> 108060 | H9: =H8*1.2 -> 115560 | I9: =I8*1.2 -> 123000
A10: =+A9+10% -> 0.7 | B10: =B8*1.4 -> 76090 | C10: =C8*1.4 -> 87010 | D10: =D8*1.4 -> 97860 | E10: =E8*1.4 -> 108710 | F10: =F8*1.4 -> 117390 | G10: =G8*1.4 -> 126070 | H10: =H8*1.4 -> 134820 | I10: =I8*1.4 -> 143500
A11: =+A10+10% -> 0.8 | B11: =B8*1.6 -> 86960 | C11: =C8*1.6 -> 99440 | D11: =D8*1.6 -> 111840 | E11: =E8*1.6 -> 124240 | F11: =F8*1.6 -> 134160 | G11: =G8*1.6 -> 144080 | H11: =H8*1.6 -> 154080 | I11: =I8*1.6 -> 164000
A12: =+A11+10% -> 0.9 | B12: =B8*1.8 -> 97830 | C12: =C8*1.8 -> 111870 | D12: =D8*1.8 -> 125820 | E12: =E8*1.8 -> 139770 | F12: =F8*1.8 -> 150930 | G12: =G8*1.8 -> 162090 | H12: =H8*1.8 -> 173340 | I12: =I8*1.8 -> 184500
A13: =+A12+10% -> 1 | B13: =B8*2 -> 108700 | C13: =C8*2 -> 124300 | D13: =D8*2 -> 139800 | E13: =E8*2 -> 155300 | F13: =F8*2 -> 167700 | G13: =G8*2 -> 180100 | H13: =H8*2 -> 192600 | I13: =I8*2 -> 205000
A14: =+A13+10% -> 1.1 | B14: =B8*2.2 -> 119570 | C14: =C8*2.2 -> 136730 | D14: =D8*2.2 -> 153780 | E14: =E8*2.2 -> 170830 | F14: =F8*2.2 -> 184470 | G14: =G8*2.2 -> 198110 | H14: =H8*2.2 -> 211860 | I14: =I8*2.2 -> 225500
A15: =+A14+10% -> 1.2 | B15: =B8*2.4 -> 130440 | C15: =C8*2.4 -> 149160 | D15: =D8*2.4 -> 167760 | E15: =E8*2.4 -> 186360 | F15: =F8*2.4 -> 201240 | G15: =G8*2.4 -> 216120 | H15: =H8*2.4 -> 231120 | I15: =I8*2.4 -> 246000
A16: =+A15+10% -> 1.3 | B16: =B8*2.6 -> 141310 | C16: =C8*2.6 -> 161590 | D16: =D8*2.6 -> 181740 | E16: =E8*2.6 -> 201890 | F16: =F8*2.6 -> 218010 | G16: =G8*2.6 -> 234130 | H16: =H8*2.6 -> 250380 | I16: =I8*2.6 -> 266500
A17: =+A16+10% -> 1.4 | B17: =B8*2.8 -> 152180 | C17: =C8*2.8 -> 174020 | D17: =D8*2.8 -> 195720 | E17: =E8*2.8 -> 217420 | F17: =F8*2.8 -> 234780 | G17: =G8*2.8 -> 252140 | H17: =H8*2.8 -> 269640 | I17: =I8*2.8 -> 287000
A18: =+A17+10% -> 1.5 | B18: =B8*3 -> 163050 | C18: =C8*3 -> 186450 | D18: =D8*3 -> 209700 | E18: =E8*3 -> 232950 | F18: =F8*3 -> 251550 | G18: =G8*3 -> 270150 | H18: =H8*3 -> 288900 | I18: =I8*3 -> 307500
A19: =+A18+10% -> 1.6 | B19: =B8*3.2 -> 173920 | C19: =C8*3.2 -> 198880 | D19: =D8*3.2 -> 223680 | E19: =E8*3.2 -> 248480 | F19: =F8*3.2 -> 268320 | G19: =G8*3.2 -> 288160 | H19: =H8*3.2 -> 308160 | I19: =I8*3.2 -> 328000
A20: =+A19+10% -> 1.7 | B20: =B8*3.4 -> 184790 | C20: =C8*3.4 -> 211310 | D20: =D8*3.4 -> 237660 | E20: =E8*3.4 -> 264010 | F20: =F8*3.4 -> 285090 | G20: =G8*3.4 -> 306170 | H20: =H8*3.4 -> 327420 | I20: =I8*3.4 -> 348500
A21: =+A20+10% -> 1.8 | B21: =B8*3.6 -> 195660 | C21: =C8*3.6 -> 223740 | D21: =D8*3.6 -> 251640 | E21: =E8*3.6 -> 279540 | F21: =F8*3.6 -> 301860 | G21: =G8*3.6 -> 324180 | H21: =H8*3.6 -> 346680 | I21: =I8*3.6 -> 369000
A22: =+A21+10% -> 1.9 | B22: =B8*3.8 -> 206530 | C22: =C8*3.8 -> 236170 | D22: =D8*3.8 -> 265620 | E22: =E8*3.8 -> 295070 | F22: =F8*3.8 -> 318630 | G22: =G8*3.8 -> 342190 | H22: =H8*3.8 -> 365940 | I22: =I8*3.8 -> 389500
A23: =+A22+10% -> 2 | B23: =B8*4 -> 217400 | C23: =C8*4 -> 248600 | D23: =D8*4 -> 279600 | E23: =E8*4 -> 310600 | F23: =F8*4 -> 335400 | G23: =G8*4 -> 360200 | H23: =H8*4 -> 385200 | I23: =I8*4 -> 410000
A24: =+A23+10% -> 2.1 | B24: =B8*4.2 -> 228270 | C24: =C8*4.2 -> 261030 | D24: =D8*4.2 -> 293580 | E24: =E8*4.2 -> 326130 | F24: =F8*4.2 -> 352170 | G24: =G8*4.2 -> 378210 | H24: =H8*4.2 -> 404460 | I24: =I8*4.2 -> 430500
A25: =+A24+10% -> 2.2 | B25: =B8*4.4 -> 239140 | C25: =C8*4.4 -> 273460 | D25: =D8*4.4 -> 307560 | E25: =E8*4.4 -> 341660 | F25: =F8*4.4 -> 368940 | G25: =G8*4.4 -> 396220 | H25: =H8*4.4 -> 423720 | I25: =I8*4.4 -> 451000
A26: =+A25+10% -> 2.3 | B26: =B8*4.6 -> 250010 | C26: =C8*4.6 -> 285890 | D26: =D8*4.6 -> 321540 | E26: =E8*4.6 -> 357190 | F26: =F8*4.6 -> 385710 | G26: =G8*4.6 -> 414230 | H26: =H8*4.6 -> 442980 | I26: =I8*4.6 -> 471500
A27: =+A26+10% -> 2.4 | B27: =B8*4.8 -> 260880 | C27: =C8*4.8 -> 298320 | D27: =D8*4.8 -> 335520 | E27: =E8*4.8 -> 372720 | F27: =F8*4.8 -> 402480 | G27: =G8*4.8 -> 432240 | H27: =H8*4.8 -> 462240 | I27: =I8*4.8 -> 492000
A28: =+A27+10% -> 2.5 | B28: =B8*5 -> 271750 | C28: =C8*5 -> 310750 | D28: =D8*5 -> 349500 | E28: =E8*5 -> 388250 | F28: =F8*5 -> 419250 | G28: =G8*5 -> 450250 | H28: =H8*5 -> 481500 | I28: =I8*5 -> 512500

Sheet Feeder Tables
A1: New Construction/Special Needs
A2: Preservation/Rehab

Sheet AMI Table
A1: ='AMI & Rent'!A3 -> 2024 Area Median Income
B2: =VLOOKUP(B3,'AMI & Rent'!$J$48:$K$55,2,FALSE) -> 0.7 | C2: =VLOOKUP(C3,'AMI & Rent'!$J$48:$K$55,2,FALSE) -> 0.8 | D2: =VLOOKUP(D3,'AMI & Rent'!$J$48:$K$55,2,FALSE) -> 0.9 | E2: =VLOOKUP(E3,'AMI & Rent'!$J$48:$K$55,2,FALSE) -> 1 | F2: =VLOOKUP(F3,'AMI & Rent'!$J$48:$K$55,2,FALSE) -> 1.08 | G2: =VLOOKUP(G3,'AMI & Rent'!$J$48:$K$55,2,FALSE) -> 1.16 | H2: =VLOOKUP(H3,'AMI & Rent'!$J$48:$K$55,2,FALSE) -> 1.24 | I2: =VLOOKUP(I3,'AMI & Rent'!$J$48:$K$55,2,FALSE) -> 1.32
B3: 1 | C3: =B3+1 -> 2 | D3: =C3+1 -> 3 | E3: =D3+1 -> 4 | F3: =E3+1 -> 5 | G3: =F3+1 -> 6 | H3: =G3+1 -> 7 | I3: =H3+1 -> 8
A4: 0.1 | B4: =IF($A4=50%,CEILING(MROUND(MROUND('AMI & Rent'!$A$5*50%,50)*$A4/50%,50)*B$2,50),CEILING(MROUND('AMI & Rent'!$A$5*50%,50)*B$2,50)*$A4/50%) -> 10880 | C4: =IF($A4=50%,CEILING(MROUND(MROUND('AMI & Rent'!$A$5*50%,50)*$A4/50%,50)*C$2,50),CEILING(MROUND('AMI & Rent'!$A$5*50%,50)*C$2,50)*$A4/50%) -> 12430 | D4: =IF($A4=50%,CEILING(MROUND(MROUND('AMI & Rent'!$A$5*50%,50)*$A4/50%,50)*D$2,50),CEILING(MROUND('AMI & Rent'!$A$5*50%,50)*D$2,50)*$A4/50%) -> 13980 | E4: =IF($A4=50%,CEILING(MROUND(MROUND('AMI & Rent'!$A$5*50%,50)*$A4/50%,50)*E$2,50),CEILING(MROUND('AMI & Rent'!$A$5*50%,50)*E$2,50)*$A4/50%) -> 15530 | F4: =IF($A4=50%,CEILING(MROUND(MROUND('AMI & Rent'!$A$5*50%,50)*$A4/50%,50)*F$2,50),CEILING(MROUND('AMI & Rent'!$A$5*50%,50)*F$2,50)*$A4/50%) -> 16780 | G4: =IF($A4=50%,CEILING(MROUND(MROUND('AMI & Rent'!$A$5*50%,50)*$A4/50%,50)*G$2,50),CEILING(MROUND('AMI & Rent'!$A$5*50%,50)*G$2,50)*$A4/50%) -> 18020 | H4: =IF($A4=50%,CEILING(MROUND(MROUND('AMI & Rent'!$A$5*50%,50)*$A4/50%,50)*H$2,50),CEILING(MROUND('AMI & Rent'!$A$5*50%,50)*H$2,50)*$A4/50%) -> 19260 | I4: =IF($A4=50%,CEILING(MROUND(MROUND('AMI & Rent'!$A$5*50%,50)*$A4/50%,50)*I$2,50),CEILING(MROUND('AMI & Rent'!$A$5*50%,50)*I$2,50)*$A4/50%) -> 20500
A5: =+A4+10% -> 0.2 | B5: =IF($A5=50%,CEILING(MROUND(MROUND('AMI & Rent'!$A$5*50%,50)*$A5/50%,50)*B$2,50),CEILING(MROUND('AMI & Rent'!$A$5*50%,50)*B$2,50)*$A5/50%) -> 21760 | C5: =IF($A5=50%,CEILING(MROUND(MROUND('AMI & Rent'!$A$5*50%,50)*$A5/50%,50)*C$2,50),CEILING(MROUND('AMI & Rent'!$A$5*50%,50)*C$2,50)*$A5/50%) -> 24860 | D5: =IF($A5=50%,CEILING(MROUND(MROUND('AMI & Rent'!$A$5*50%,50)*$A5/50%,50)*D$2,50),CEILING(MROUND('AMI & Rent'!$A$5*50%,50)*D$2,50)*$A5/50%) -> 27960 | E5: =IF($A5=50%,CEILING(MROUND(MROUND('AMI & Rent'!$A$5*50%,50)*$A5/50%,50)*E$2,50),CEILING(MROUND('AMI & Rent'!$A$5*50%,50)*E$2,50)*$A5/50%) -> 31060 | F5: =IF($A5=50%,CEILING(MROUND(MROUND('AMI & Rent'!$A$5*50%,50)*$A5/50%,50)*F$2,50),CEILING(MROUND('AMI & Rent'!$A$5*50%,50)*F$2,50)*$A5/50%) -> 33560 | G5: =IF($A5=50%,CEILING(MROUND(MROUND('AMI & Rent'!$A$5*50%,50)*$A5/50%,50)*G$2,50),CEILING(MROUND('AMI & Rent'!$A$5*50%,50)*G$2,50)*$A5/50%) -> 36040 | H5: =IF($A5=50%,CEILING(MROUND(MROUND('AMI & Rent'!$A$5*50%,50)*$A5/50%,50)*H$2,50),CEILING(MROUND('AMI & Rent'!$A$5*50%,50)*H$2,50)*$A5/50%) -> 38520 | I5: =IF($A5=50%,CEILING(MROUND(MROUND('AMI & Rent'!$A$5*50%,50)*$A5/50%,50)*I$2,50),CEILING(MROUND('AMI & Rent'!$A$5*50%,50)*I$2,50)*$A5/50%) -> 41000
A6: =+A5+10% -> 0.3 | B6: =IF($A6=50%,CEILING(MROUND(MROUND('AMI & Rent'!$A$5*50%,50)*$A6/50%,50)*B$2,50),CEILING(MROUND('AMI & Rent'!$A$5*50%,50)*B$2,50)*$A6/50%) -> 32640 | C6: =IF($A6=50%,CEILING(MROUND(MROUND('AMI & Rent'!$A$5*50%,50)*$A6/50%,50)*C$2,50),CEILING(MROUND('AMI & Rent'!$A$5*50%,50)*C$2,50)*$A6/50%) -> 37290 | D6: =IF($A6=50%,CEILING(MROUND(MROUND('AMI & Rent'!$A$5*50%,50)*$A6/50%,50)*D$2,50),CEILING(MROUND('AMI & Rent'!$A$5*50%,50)*D$2,50)*$A6/50%) -> 41940 | E6: =IF($A6=50%,CEILING(MROUND(MROUND('AMI & Rent'!$A$5*50%,50)*$A6/50%,50)*E$2,50),CEILING(MROUND('AMI & Rent'!$A$5*50%,50)*E$2,50)*$A6/50%) -> 46590 | F6: =IF($A6=50%,CEILING(MROUND(MROUND('AMI & Rent'!$A$5*50%,50)*$A6/50%,50)*F$2,50),CEILING(MROUND('AMI & Rent'!$A$5*50%,50)*F$2,50)*$A6/50%) -> 50340 | G6: =IF($A6=50%,CEILING(MROUND(MROUND('AMI & Rent'!$A$5*50%,50)*$A6/50%,50)*G$2,50),CEILING(MROUND('AMI & Rent'!$A$5*50%,50)*G$2,50)*$A6/50%) -> 54060 | H6: =IF($A6=50%,CEILING(MROUND(MROUND('AMI & Rent'!$A$5*50%,50)*$A6/50%,50)*H$2,50),CEILING(MROUND('AMI & Rent'!$A$5*50%,50)*H$2,50)*$A6/50%) -> 57780 | I6: =IF($A6=50%,CEILING(MROUND(MROUND('AMI & Rent'!$A$5*50%,50)*$A6/50%,50)*I$2,50),CEILING(MROUND('AMI & Rent'!$A$5*50%,50)*I$2,50)*$A6/50%) -> 61500
A7: =+A6+10% -> 0.4 | B7: =IF($A7=50%,CEILING(MROUND(MROUND('AMI & Rent'!$A$5*50%,50)*$A7/50%,50)*B$2,50),CEILING(MROUND('AMI & Rent'!$A$5*50%,50)*B$2,50)*$A7/50%) -> 43520 | C7: =IF($A7=50%,CEILING(MROUND(MROUND('AMI & Rent'!$A$5*50%,50)*$A7/50%,50)*C$2,50),CEILING(MROUND('AMI & Rent'!$A$5*50%,50)*C$2,50)*$A7/50%) -> 49720 | D7: =IF($A7=50%,CEILING(MROUND(MROUND('AMI & Rent'!$A$5*50%,50)*$A7/50%,50)*D$2,50),CEILING(MROUND('AMI & Rent'!$A$5*50%,50)*D$2,50)*$A7/50%) -> 55920 | E7: =IF($A7=50%,CEILING(MROUND(MROUND('AMI & Rent'!$A$5*50%,50)*$A7/50%,50)*E$2,50),CEILING(MROUND('AMI & Rent'!$A$5*50%,50)*E$2,50)*$A7/50%) -> 62120 | F7: =IF($A7=50%,CEILING(MROUND(MROUND('AMI & Rent'!$A$5*50%,50)*$A7/50%,50)*F$2,50),CEILING(MROUND('AMI & Rent'!$A$5*50%,50)*F$2,50)*$A7/50%) -> 67120 | G7: =IF($A7=50%,CEILING(MROUND(MROUND('AMI & Rent'!$A$5*50%,50)*$A7/50%,50)*G$2,50),CEILING(MROUND('AMI & Rent'!$A$5*50%,50)*G$2,50)*$A7/50%) -> 72080 | H7: =IF($A7=50%,CEILING(MROUND(MROUND('AMI & Rent'!$A$5*50%,50)*$A7/50%,50)*H$2,50),CEILING(MROUND('AMI & Rent'!$A$5*50%,50)*H$2,50)*$A7/50%) -> 77040 | I7: =IF($A7=50%,CEILING(MROUND(MROUND('AMI & Rent'!$A$5*50%,50)*$A7/50%,50)*I$2,50),CEILING(MROUND('AMI & Rent'!$A$5*50%,50)*I$2,50)*$A7/50%) -> 82000
A8: =+A7+10% -> 0.5 | B8: =IF($A8=50%,CEILING(MROUND(MROUND('AMI & Rent'!$A$5*50%,50)*$A8/50%,50)*B$2,50),CEILING(MROUND('AMI & Rent'!$A$5*50%,50)*B$2,50)*$A8/50%) -> 54400 | C8: =IF($A8=50%,CEILING(MROUND(MROUND('AMI & Rent'!$A$5*50%,50)*$A8/50%,50)*C$2,50),CEILING(MROUND('AMI & Rent'!$A$5*50%,50)*C$2,50)*$A8/50%) -> 62150 | D8: =IF($A8=50%,CEILING(MROUND(MROUND('AMI & Rent'!$A$5*50%,50)*$A8/50%,50)*D$2,50),CEILING(MROUND('AMI & Rent'!$A$5*50%,50)*D$2,50)*$A8/50%) -> 69900 | E8: =IF($A8=50%,CEILING(MROUND(MROUND('AMI & Rent'!$A$5*50%,50)*$A8/50%,50)*E$2,50),CEILING(MROUND('AMI & Rent'!$A$5*50%,50)*E$2,50)*$A8/50%) -> 77650 | F8: =IF($A8=50%,CEILING(MROUND(MROUND('AMI & Rent'!$A$5*50%,50)*$A8/50%,50)*F$2,50),CEILING(MROUND('AMI & Rent'!$A$5*50%,50)*F$2,50)*$A8/50%) -> 83900 | G8: =IF($A8=50%,CEILING(MROUND(MROUND('AMI & Rent'!$A$5*50%,50)*$A8/50%,50)*G$2,50),CEILING(MROUND('AMI & Rent'!$A$5*50%,50)*G$2,50)*$A8/50%) -> 90100 | H8: =IF($A8=50%,CEILING(MROUND(MROUND('AMI & Rent'!$A$5*50%,50)*$A8/50%,50)*H$2,50),CEILING(MROUND('AMI & Rent'!$A$5*50%,50)*H$2,50)*$A8/50%) -> 96300 | I8: =IF($A8=50%,CEILING(MROUND(MROUND('AMI & Rent'!$A$5*50%,50)*$A8/50%,50)*I$2,50),CEILING(MROUND('AMI & Rent'!$A$5*50%,50)*I$2,50)*$A8/50%) -> 102500
A9: =+A8+10% -> 0.6 | B9: =IF($A9=50%,CEILING(MROUND(MROUND('AMI & Rent'!$A$5*50%,50)*$A9/50%,50)*B$2,50),CEILING(MROUND('AMI & Rent'!$A$5*50%,50)*B$2,50)*$A9/50%) -> 65280 | C9: =IF($A9=50%,CEILING(MROUND(MROUND('AMI & Rent'!$A$5*50%,50)*$A9/50%,50)*C$2,50),CEILING(MROUND('AMI & Rent'!$A$5*50%,50)*C$2,50)*$A9/50%) -> 74580 | D9: =IF($A9=50%,CEILING(MROUND(MROUND('AMI & Rent'!$A$5*50%,50)*$A9/50%,50)*D$2,50),CEILING(MROUND('AMI & Rent'!$A$5*50%,50)*D$2,50)*$A9/50%) -> 83880 | E9: =IF($A9=50%,CEILING(MROUND(MROUND('AMI & Rent'!$A$5*50%,50)*$A9/50%,50)*E$2,50),CEILING(MROUND('AMI & Rent'!$A$5*50%,50)*E$2,50)*$A9/50%) -> 93180 | F9: =IF($A9=50%,CEILING(MROUND(MROUND('AMI & Rent'!$A$5*50%,50)*$A9/50%,50)*F$2,50),CEILING(MROUND('AMI & Rent'!$A$5*50%,50)*F$2,50)*$A9/50%) -> 100680 | G9: =IF($A9=50%,CEILING(MROUND(MROUND('AMI & Rent'!$A$5*50%,50)*$A9/50%,50)*G$2,50),CEILING(MROUND('AMI & Rent'!$A$5*50%,50)*G$2,50)*$A9/50%) -> 108120 | H9: =IF($A9=50%,CEILING(MROUND(MROUND('AMI & Rent'!$A$5*50%,50)*$A9/50%,50)*H$2,50),CEILING(MROUND('AMI & Rent'!$A$5*50%,50)*H$2,50)*$A9/50%) -> 115560 | I9: =IF($A9=50%,CEILING(MROUND(MROUND('AMI & Rent'!$A$5*50%,50)*$A9/50%,50)*I$2,50),CEILING(MROUND('AMI & Rent'!$A$5*50%,50)*I$2,50)*$A9/50%) -> 123000
A10: =+A9+10% -> 0.7 | B10: =IF($A10=50%,CEILING(MROUND(MROUND('AMI & Rent'!$A$5*50%,50)*$A10/50%,50)*B$2,50),CEILING(MROUND('AMI & Rent'!$A$5*50%,50)*B$2,50)*$A10/50%) -> 76160 | C10: =IF($A10=50%,CEILING(MROUND(MROUND('AMI & Rent'!$A$5*50%,50)*$A10/50%,50)*C$2,50),CEILING(MROUND('AMI & Rent'!$A$5*50%,50)*C$2,50)*$A10/50%) -> 87010 | D10: =IF($A10=50%,CEILING(MROUND(MROUND('AMI & Rent'!$A$5*50%,50)*$A10/50%,50)*D$2,50),CEILING(MROUND('AMI & Rent'!$A$5*50%,50)*D$2,50)*$A10/50%) -> 97860 | E10: =IF($A10=50%,CEILING(MROUND(MROUND('AMI & Rent'!$A$5*50%,50)*$A10/50%,50)*E$2,50),CEILING(MROUND('AMI & Rent'!$A$5*50%,50)*E$2,50)*$A10/50%) -> 108710 | F10: =IF($A10=50%,CEILING(MROUND(MROUND('AMI & Rent'!$A$5*50%,50)*$A10/50%,50)*F$2,50),CEILING(MROUND('AMI & Rent'!$A$5*50%,50)*F$2,50)*$A10/50%) -> 117460 | G10: =IF($A10=50%,CEILING(MROUND(MROUND('AMI & Rent'!$A$5*50%,50)*$A10/50%,50)*G$2,50),CEILING(MROUND('AMI & Rent'!$A$5*50%,50)*G$2,50)*$A10/50%) -> 126140 | H10: =IF($A10=50%,CEILING(MROUND(MROUND('AMI & Rent'!$A$5*50%,50)*$A10/50%,50)*H$2,50),CEILING(MROUND('AMI & Rent'!$A$5*50%,50)*H$2,50)*$A10/50%) -> 134820 | I10: =IF($A10=50%,CEILING(MROUND(MROUND('AMI & Rent'!$A$5*50%,50)*$A10/50%,50)*I$2,50),CEILING(MROUND('AMI & Rent'!$A$5*50%,50)*I$2,50)*$A10/50%) -> 143500
A11: =+A10+10% -> 0.8 | B11: =IF($A11=50%,CEILING(MROUND(MROUND('AMI & Rent'!$A$5*50%,50)*$A11/50%,50)*B$2,50),CEILING(MROUND('AMI & Rent'!$A$5*50%,50)*B$2,50)*$A11/50%) -> 87040 | C11: =IF($A11=50%,CEILING(MROUND(MROUND('AMI & Rent'!$A$5*50%,50)*$A11/50%,50)*C$2,50),CEILING(MROUND('AMI & Rent'!$A$5*50%,50)*C$2,50)*$A11/50%) -> 99440 | D11: =IF($A11=50%,CEILING(MROUND(MROUND('AMI & Rent'!$A$5*50%,50)*$A11/50%,50)*D$2,50),CEILING(MROUND('AMI & Rent'!$A$5*50%,50)*D$2,50)*$A11/50%) -> 111840 | E11: =IF($A11=50%,CEILING(MROUND(MROUND('AMI & Rent'!$A$5*50%,50)*$A11/50%,50)*E$2,50),CEILING(MROUND('AMI & Rent'!$A$5*50%,50)*E$2,50)*$A11/50%) -> 124240 | F11: =IF($A11=50%,CEILING(MROUND(MROUND('AMI & Rent'!$A$5*50%,50)*$A11/50%,50)*F$2,50),CEILING(MROUND('AMI & Rent'!$A$5*50%,50)*F$2,50)*$A11/50%) -> 134240 | G11: =IF($A11=50%,CEILING(MROUND(MROUND('AMI & Rent'!$A$5*50%,50)*$A11/50%,50)*G$2,50),CEILING(MROUND('AMI & Rent'!$A$5*50%,50)*G$2,50)*$A11/50%) -> 144160 | H11: =IF($A11=50%,CEILING(MROUND(MROUND('AMI & Rent'!$A$5*50%,50)*$A11/50%,50)*H$2,50),CEILING(MROUND('AMI & Rent'!$A$5*50%,50)*H$2,50)*$A11/50%) -> 154080 | I11: =IF($A11=50%,CEILING(MROUND(MROUND('AMI & Rent'!$A$5*50%,50)*$A11/50%,50)*I$2,50),CEILING(MROUND('AMI & Rent'!$A$5*50%,50)*I$2,50)*$A11/50%) -> 164000
A12: =+A11+10% -> 0.9 | B12: =IF($A12=50%,CEILING(MROUND(MROUND('AMI & Rent'!$A$5*50%,50)*$A12/50%,50)*B$2,50),CEILING(MROUND('AMI & Rent'!$A$5*50%,50)*B$2,50)*$A12/50%) -> 97920 | C12: =IF($A12=50%,CEILING(MROUND(MROUND('AMI & Rent'!$A$5*50%,50)*$A12/50%,50)*C$2,50),CEILING(MROUND('AMI & Rent'!$A$5*50%,50)*C$2,50)*$A12/50%) -> 111870 | D12: =IF($A12=50%,CEILING(MROUND(MROUND('AMI & Rent'!$A$5*50%,50)*$A12/50%,50)*D$2,50),CEILING(MROUND('AMI & Rent'!$A$5*50%,50)*D$2,50)*$A12/50%) -> 125820 | E12: =IF($A12=50%,CEILING(MROUND(MROUND('AMI & Rent'!$A$5*50%,50)*$A12/50%,50)*E$2,50),CEILING(MROUND('AMI & Rent'!$A$5*50%,50)*E$2,50)*$A12/50%) -> 139770 | F12: =IF($A12=50%,CEILING(MROUND(MROUND('AMI & Rent'!$A$5*50%,50)*$A12/50%,50)*F$2,50),CEILING(MROUND('AMI & Rent'!$A$5*50%,50)*F$2,50)*$A12/50%) -> 151020 | G12: =IF($A12=50%,CEILING(MROUND(MROUND('AMI & Rent'!$A$5*50%,50)*$A12/50%,50)*G$2,50),CEILING(MROUND('AMI & Rent'!$A$5*50%,50)*G$2,50)*$A12/50%) -> 162180 | H12: =IF($A12=50%,CEILING(MROUND(MROUND('AMI & Rent'!$A$5*50%,50)*$A12/50%,50)*H$2,50),CEILING(MROUND('AMI & Rent'!$A$5*50%,50)*H$2,50)*$A12/50%) -> 173340 | I12: =IF($A12=50%,CEILING(MROUND(MROUND('AMI & Rent'!$A$5*50%,50)*$A12/50%,50)*I$2,50),CEILING(MROUND('AMI & Rent'!$A$5*50%,50)*I$2,50)*$A12/50%) -> 184500
A13: =+A12+10% -> 1 | B13: =IF($A13=50%,CEILING(MROUND(MROUND('AMI & Rent'!$A$5*50%,50)*$A13/50%,50)*B$2,50),CEILING(MROUND('AMI & Rent'!$A$5*50%,50)*B$2,50)*$A13/50%) -> 108800 | C13: =IF($A13=50%,CEILING(MROUND(MROUND('AMI & Rent'!$A$5*50%,50)*$A13/50%,50)*C$2,50),CEILING(MROUND('AMI & Rent'!$A$5*50%,50)*C$2,50)*$A13/50%) -> 124300 | D13: =IF($A13=50%,CEILING(MROUND(MROUND('AMI & Rent'!$A$5*50%,50)*$A13/50%,50)*D$2,50),CEILING(MROUND('AMI & Rent'!$A$5*50%,50)*D$2,50)*$A13/50%) -> 139800 | E13: =IF($A13=50%,CEILING(MROUND(MROUND('AMI & Rent'!$A$5*50%,50)*$A13/50%,50)*E$2,50),CEILING(MROUND('AMI & Rent'!$A$5*50%,50)*E$2,50)*$A13/50%) -> 155300 | F13: =IF($A13=50%,CEILING(MROUND(MROUND('AMI & Rent'!$A$5*50%,50)*$A13/50%,50)*F$2,50),CEILING(MROUND('AMI & Rent'!$A$5*50%,50)*F$2,50)*$A13/50%) -> 167800 | G13: =IF($A13=50%,CEILING(MROUND(MROUND('AMI & Rent'!$A$5*50%,50)*$A13/50%,50)*G$2,50),CEILING(MROUND('AMI & Rent'!$A$5*50%,50)*G$2,50)*$A13/50%) -> 180200 | H13: =IF($A13=50%,CEILING(MROUND(MROUND('AMI & Rent'!$A$5*50%,50)*$A13/50%,50)*H$2,50),CEILING(MROUND('AMI & Rent'!$A$5*50%,50)*H$2,50)*$A13/50%) -> 192600 | I13: =IF($A13=50%,CEILING(MROUND(MROUND('AMI & Rent'!$A$5*50%,50)*$A13/50%,50)*I$2,50),CEILING(MROUND('AMI & Rent'!$A$5*50%,50)*I$2,50)*$A13/50%) -> 205000
A14: =+A13+10% -> 1.1 | B14: =IF($A14=50%,CEILING(MROUND(MROUND('AMI & Rent'!$A$5*50%,50)*$A14/50%,50)*B$2,50),CEILING(MROUND('AMI & Rent'!$A$5*50%,50)*B$2,50)*$A14/50%) -> 119680 | C14: =IF($A14=50%,CEILING(MROUND(MROUND('AMI & Rent'!$A$5*50%,50)*$A14/50%,50)*C$2,50),CEILING(MROUND('AMI & Rent'!$A$5*50%,50)*C$2,50)*$A14/50%) -> 136730 | D14: =IF($A14=50%,CEILING(MROUND(MROUND('AMI & Rent'!$A$5*50%,50)*$A14/50%,50)*D$2,50),CEILING(MROUND('AMI & Rent'!$A$5*50%,50)*D$2,50)*$A14/50%) -> 153780 | E14: =IF($A14=50%,CEILING(MROUND(MROUND('AMI & Rent'!$A$5*50%,50)*$A14/50%,50)*E$2,50),CEILING(MROUND('AMI & Rent'!$A$5*50%,50)*E$2,50)*$A14/50%) -> 170830 | F14: =IF($A14=50%,CEILING(MROUND(MROUND('AMI & Rent'!$A$5*50%,50)*$A14/50%,50)*F$2,50),CEILING(MROUND('AMI & Rent'!$A$5*50%,50)*F$2,50)*$A14/50%) -> 184580 | G14: =IF($A14=50%,CEILING(MROUND(MROUND('AMI & Rent'!$A$5*50%,50)*$A14/50%,50)*G$2,50),CEILING(MROUND('AMI & Rent'!$A$5*50%,50)*G$2,50)*$A14/50%) -> 198220 | H14: =IF($A14=50%,CEILING(MROUND(MROUND('AMI & Rent'!$A$5*50%,50)*$A14/50%,50)*H$2,50),CEILING(MROUND('AMI & Rent'!$A$5*50%,50)*H$2,50)*$A14/50%) -> 211860 | I14: =IF($A14=50%,CEILING(MROUND(MROUND('AMI & Rent'!$A$5*50%,50)*$A14/50%,50)*I$2,50),CEILING(MROUND('AMI & Rent'!$A$5*50%,50)*I$2,50)*$A14/50%) -> 225500
A15: =+A14+10% -> 1.2 | B15: =IF($A15=50%,CEILING(MROUND(MROUND('AMI & Rent'!$A$5*50%,50)*$A15/50%,50)*B$2,50),CEILING(MROUND('AMI & Rent'!$A$5*50%,50)*B$2,50)*$A15/50%) -> 130560 | C15: =IF($A15=50%,CEILING(MROUND(MROUND('AMI & Rent'!$A$5*50%,50)*$A15/50%,50)*C$2,50),CEILING(MROUND('AMI & Rent'!$A$5*50%,50)*C$2,50)*$A15/50%) -> 149160 | D15: =IF($A15=50%,CEILING(MROUND(MROUND('AMI & Rent'!$A$5*50%,50)*$A15/50%,50)*D$2,50),CEILING(MROUND('AMI & Rent'!$A$5*50%,50)*D$2,50)*$A15/50%) -> 167760 | E15: =IF($A15=50%,CEILING(MROUND(MROUND('AMI & Rent'!$A$5*50%,50)*$A15/50%,50)*E$2,50),CEILING(MROUND('AMI & Rent'!$A$5*50%,50)*E$2,50)*$A15/50%) -> 186360 | F15: =IF($A15=50%,CEILING(MROUND(MROUND('AMI & Rent'!$A$5*50%,50)*$A15/50%,50)*F$2,50),CEILING(MROUND('AMI & Rent'!$A$5*50%,50)*F$2,50)*$A15/50%) -> 201360 | G15: =IF($A15=50%,CEILING(MROUND(MROUND('AMI & Rent'!$A$5*50%,50)*$A15/50%,50)*G$2,50),CEILING(MROUND('AMI & Rent'!$A$5*50%,50)*G$2,50)*$A15/50%) -> 216240 | H15: =IF($A15=50%,CEILING(MROUND(MROUND('AMI & Rent'!$A$5*50%,50)*$A15/50%,50)*H$2,50),CEILING(MROUND('AMI & Rent'!$A$5*50%,50)*H$2,50)*$A15/50%) -> 231120 | I15: =IF($A15=50%,CEILING(MROUND(MROUND('AMI & Rent'!$A$5*50%,50)*$A15/50%,50)*I$2,50),CEILING(MROUND('AMI & Rent'!$A$5*50%,50)*I$2,50)*$A15/50%) -> 246000
A16: =+A15+10% -> 1.3 | B16: =IF($A16=50%,CEILING(MROUND(MROUND('AMI & Rent'!$A$5*50%,50)*$A16/50%,50)*B$2,50),CEILING(MROUND('AMI & Rent'!$A$5*50%,50)*B$2,50)*$A16/50%) -> 141440 | C16: =IF($A16=50%,CEILING(MROUND(MROUND('AMI & Rent'!$A$5*50%,50)*$A16/50%,50)*C$2,50),CEILING(MROUND('AMI & Rent'!$A$5*50%,50)*C$2,50)*$A16/50%) -> 161590 | D16: =IF($A16=50%,CEILING(MROUND(MROUND('AMI & Rent'!$A$5*50%,50)*$A16/50%,50)*D$2,50),CEILING(MROUND('AMI & Rent'!$A$5*50%,50)*D$2,50)*$A16/50%) -> 181740 | E16: =IF($A16=50%,CEILING(MROUND(MROUND('AMI & Rent'!$A$5*50%,50)*$A16/50%,50)*E$2,50),CEILING(MROUND('AMI & Rent'!$A$5*50%,50)*E$2,50)*$A16/50%) -> 201890 | F16: =IF($A16=50%,CEILING(MROUND(MROUND('AMI & Rent'!$A$5*50%,50)*$A16/50%,50)*F$2,50),CEILING(MROUND('AMI & Rent'!$A$5*50%,50)*F$2,50)*$A16/50%) -> 218140 | G16: =IF($A16=50%,CEILING(MROUND(MROUND('AMI & Rent'!$A$5*50%,50)*$A16/50%,50)*G$2,50),CEILING(MROUND('AMI & Rent'!$A$5*50%,50)*G$2,50)*$A16/50%) -> 234260 | H16: =IF($A16=50%,CEILING(MROUND(MROUND('AMI & Rent'!$A$5*50%,50)*$A16/50%,50)*H$2,50),CEILING(MROUND('AMI & Rent'!$A$5*50%,50)*H$2,50)*$A16/50%) -> 250380 | I16: =IF($A16=50%,CEILING(MROUND(MROUND('AMI & Rent'!$A$5*50%,50)*$A16/50%,50)*I$2,50),CEILING(MROUND('AMI & Rent'!$A$5*50%,50)*I$2,50)*$A16/50%) -> 266500
... A28: =+A27+10% -> 2.5 | B28: =IF($A28=50%,CEILING(MROUND(MROUND('AMI & Rent'!$A$5*50%,50)*$A28/50%,50)*B$2,50),CEILING(MROUND('AMI & Rent'!$A$5*50%,50)*B$2,50)*$A28/50%) -> 272000 | C28: =IF($A28=50%,CEILING(MROUND(MROUND('AMI & Rent'!$A$5*50%,50)*$A28/50%,50)*C$2,50),CEILING(MROUND('AMI & Rent'!$A$5*50%,50)*C$2,50)*$A28/50%) -> 310750 | D28: =IF($A28=50%,CEILING(MROUND(MROUND('AMI & Rent'!$A$5*50%,50)*$A28/50%,50)*D$2,50),CEILING(MROUND('AMI & Rent'!$A$5*50%,50)*D$2,50)*$A28/50%) -> 349500 | E28: =IF($A28=50%,CEILING(MROUND(MROUND('AMI & Rent'!$A$5*50%,50)*$A28/50%,50)*E$2,50),CEILING(MROUND('AMI & Rent'!$A$5*50%,50)*E$2,50)*$A28/50%) -> 388250 | F28: =IF($A28=50%,CEILING(MROUND(MROUND('AMI & Rent'!$A$5*50%,50)*$A28/50%,50)*F$2,50),CEILING(MROUND('AMI & Rent'!$A$5*50%,50)*F$2,50)*$A28/50%) -> 419500 | G28: =IF($A28=50%,CEILING(MROUND(MROUND('AMI & Rent'!$A$5*50%,50)*$A28/50%,50)*G$2,50),CEILING(MROUND('AMI & Rent'!$A$5*50%,50)*G$2,50)*$A28/50%) -> 450500 | H28: =IF($A28=50%,CEILING(MROUND(MROUND('AMI & Rent'!$A$5*50%,50)*$A28/50%,50)*H$2,50),CEILING(MROUND('AMI & Rent'!$A$5*50%,50)*H$2,50)*$A28/50%) -> 481500 | I28: =IF($A28=50%,CEILING(MROUND(MROUND('AMI & Rent'!$A$5*50%,50)*$A28/50%,50)*I$2,50),CEILING(MROUND('AMI & Rent'!$A$5*50%,50)*I$2,50)*$A28/50%) -> 512500
